Workbook

Sheet Лист4
A3: Названия строк | B3: Количество по полю Count
A4: #29074 – CruzRivera 2022 | B4: 2
A5: #36499 – Dubey 2020 | B5: 2
A6: #34723 – Grover 2022 | B6: 2
A7: #28042 – Contreras-Bolívar 2022 | B7: 2
A8: #28849 – Faron 2020 | B8: 2
A9: #28088 – Holmes 2022 | B9: 2
A10: #31452 – Filteau 2024 | B10: 2
A11: #28112 – Herda 2022 | B11: 2
A12: #36086 – Coëffier 2020 | B12: 2
A13: #28116 – Coëffier 2022 | B13: 2
A14: #28628 – Hamilton-James 2021 | B14: 2
A15: #28205 – GarrBarry 2022 | B15: 2
... A81: Общий итог | B81: 102

Sheet Source
A1: Study | B1: Count | E1: YEAR | F1: Number | G1: StrLength | I1: StrLength2 | J1: First Author | N1: Number | O1: YEAR | P1: First Author | R1: Check
A2: #28292 – Abbaspour 2021 | B2: 1 | E2: =RIGHT(A2,4) -> 2021 | F2: =RIGHT(LEFT(A2,6),5) -> 28292 | G2: =LEN(A2) -> 23 | H2: =RIGHT(A2,(G2-9)) -> Abbaspour 2021 | I2: =LEN(H2) -> 14 | J2: =LEFT(H2,(I2-5)) -> Abbaspour | N2: 28292 | O2: 2021 | P2: Abbaspour | R2: =VLOOKUP(N2,dir!B:B,1,0) -> 28292
A3: #28140 – Aguirre 2024 | B3: 1 | E3: =RIGHT(A3,4) -> 2024 | F3: =RIGHT(LEFT(A3,6),5) -> 28140 | G3: =LEN(A3) -> 21 | H3: =RIGHT(A3,(G3-9)) -> Aguirre 2024 | I3: =LEN(H3) -> 12 | J3: =LEFT(H3,(I3-5)) -> Aguirre | N3: 28140 | O3: 2024 | P3: Aguirre | R3: =VLOOKUP(N3,dir!B:B,1,0) -> 28140
A4: #32139 – Ahmadi 2024 | B4: 1 | E4: =RIGHT(A4,4) -> 2024 | F4: =RIGHT(LEFT(A4,6),5) -> 32139 | G4: =LEN(A4) -> 20 | H4: =RIGHT(A4,(G4-9)) -> Ahmadi 2024 | I4: =LEN(H4) -> 11 | J4: =LEFT(H4,(I4-5)) -> Ahmadi | N4: 32139 | O4: 2024 | P4: Ahmadi | R4: =VLOOKUP(N4,dir!B:B,1,0) -> 32139
A5: #35451 – Alavi 2021 | B5: 1 | E5: =RIGHT(A5,4) -> 2021 | F5: =RIGHT(LEFT(A5,6),5) -> 35451 | G5: =LEN(A5) -> 19 | H5: =RIGHT(A5,(G5-9)) -> Alavi 2021 | I5: =LEN(H5) -> 10 | J5: =LEFT(H5,(I5-5)) -> Alavi | N5: 35451 | O5: 2021 | P5: Alavi | R5: =VLOOKUP(N5,dir!B:B,1,0) -> 35451
A6: #28059 – Anusitviwat 2023 | B6: 1 | E6: =RIGHT(A6,4) -> 2023 | F6: =RIGHT(LEFT(A6,6),5) -> 28059 | G6: =LEN(A6) -> 25 | H6: =RIGHT(A6,(G6-9)) -> Anusitviwat 2023 | I6: =LEN(H6) -> 16 | J6: =LEFT(H6,(I6-5)) -> Anusitviwat | N6: 28059 | O6: 2023 | P6: Anusitviwat | R6: =VLOOKUP(N6,dir!B:B,1,0) -> 28059
A7: #28270 – Ballesteros-Pomar 2022 | B7: 1 | E7: =RIGHT(A7,4) -> 2022 | F7: =RIGHT(LEFT(A7,6),5) -> 28270 | G7: =LEN(A7) -> 31 | H7: =RIGHT(A7,(G7-9)) -> Ballesteros-Pomar 2022 | I7: =LEN(H7) -> 22 | J7: =LEFT(H7,(I7-5)) -> Ballesteros-Pomar | N7: 28270 | O7: 2022 | P7: Ballesteros-Pomar | R7: =VLOOKUP(N7,dir!B:B,1,0) -> 28270
A8: #28602 – Bärebring 2020 | B8: 1 | E8: =RIGHT(A8,4) -> 2020 | F8: =RIGHT(LEFT(A8,6),5) -> 28602 | G8: =LEN(A8) -> 23 | H8: =RIGHT(A8,(G8-9)) -> Bärebring 2020 | I8: =LEN(H8) -> 14 | J8: =LEFT(H8,(I8-5)) -> Bärebring | N8: 28602 | O8: 2020 | P8: Bärebring | R8: =VLOOKUP(N8,dir!B:B,1,0) -> 28602
A9: #28371 – BarretoSilva 2021 | B9: 1 | E9: =RIGHT(A9,4) -> 2021 | F9: =RIGHT(LEFT(A9,6),5) -> 28371 | G9: =LEN(A9) -> 26 | H9: =RIGHT(A9,(G9-9)) -> BarretoSilva 2021 | I9: =LEN(H9) -> 17 | J9: =LEFT(H9,(I9-5)) -> BarretoSilva | N9: 28371 | O9: 2021 | P9: BarretoSilva | R9: =VLOOKUP(N9,dir!B:B,1,0) -> 28371
A10: #33162 – Baş 2023 | B10: 1 | E10: =RIGHT(A10,4) -> 2023 | F10: =RIGHT(LEFT(A10,6),5) -> 33162 | G10: =LEN(A10) -> 17 | H10: =RIGHT(A10,(G10-9)) -> Baş 2023 | I10: =LEN(H10) -> 8 | J10: =LEFT(H10,(I10-5)) -> Baş | N10: 33162 | O10: 2023 | P10: Baş | R10: =VLOOKUP(N10,dir!B:B,1,0) -> 33162
A11: #34577 – Bea 2022 | B11: 1 | E11: =RIGHT(A11,4) -> 2022 | F11: =RIGHT(LEFT(A11,6),5) -> 34577 | G11: =LEN(A11) -> 17 | H11: =RIGHT(A11,(G11-9)) -> Bea 2022 | I11: =LEN(H11) -> 8 | J11: =LEFT(H11,(I11-5)) -> Bea | N11: 34577 | O11: 2022 | P11: Bea | R11: =VLOOKUP(N11,dir!B:B,1,0) -> 34577
A12: #28305 – Bellafronte 2021 | B12: 1 | E12: =RIGHT(A12,4) -> 2021 | F12: =RIGHT(LEFT(A12,6),5) -> 28305 | G12: =LEN(A12) -> 25 | H12: =RIGHT(A12,(G12-9)) -> Bellafronte 2021 | I12: =LEN(H12) -> 16 | J12: =LEFT(H12,(I12-5)) -> Bellafronte | N12: 28305 | O12: 2021 | P12: Bellafronte | R12: =VLOOKUP(N12,dir!B:B,1,0) -> 28305
A13: #35479 – Bellafronte 2021 | B13: 1 | E13: =RIGHT(A13,4) -> 2021 | F13: =RIGHT(LEFT(A13,6),5) -> 35479 | G13: =LEN(A13) -> 25 | H13: =RIGHT(A13,(G13-9)) -> Bellafronte 2021 | I13: =LEN(H13) -> 16 | J13: =LEFT(H13,(I13-5)) -> Bellafronte | N13: 35479 | O13: 2021 | P13: Bellafronte | R13: =VLOOKUP(N13,dir!B:B,1,0) -> 35479
... A103: #28214 – Zambone 2020 | B103: 1 | E103: =RIGHT(A103,4) -> 2020 | F103: =RIGHT(LEFT(A103,6),5) -> 28214 | G103: =LEN(A103) -> 21 | H103: =RIGHT(A103,(G103-9)) -> Zambone 2020 | I103: =LEN(H103) -> 12 | J103: =LEFT(H103,(I103-5)) -> Zambone | N103: 28214 | O103: 2020 | P103: Zambone | R103: =VLOOKUP(N103,dir!B:B,1,0) -> 28214

Sheet PIVOT
A3: Количество по полю N
A4: YEAR | B4: First Author | C4: Number | D4: Итог
A5: 2020 | B5: Bärebring | C5: 28602 | D5: 1
B6: Bosaeus | C6: 36353 | D6: 1
B7: Cavedon | C7: 36037 | D7: 1
B8: Coëffier | C8: 36086 | D8: 2
B9: deAbreu | C9: 28245 | D9: 2
B10: Dubey | C10: 36499 | D10: 2
B11: Fang | C11: 36754 | D11: 2
B12: Faron | C12: 28849 | D12: 2
B13: Golja | C13: 36200 | D13: 2
B14: Khan | C14: 36375 | D14: 1
B15: Tinsley | C15: 36542 | D15: 1
B16: Wood | C16: 36265 | D16: 1
B17: Zambone | C17: 28214 | D17: 1
A18: 2021 | B18: Abbaspour | C18: 28292 | D18: 1
B19: Alavi | C19: 35451 | D19: 1
B20: BarretoSilva | C20: 28371 | D20: 1
B21: Bellafronte | C21: 28305 | D21: 1
C22: 35479 | D22: 1
B23: Boykin | C23: 35272 | D23: 1
B24: Brewer | C24: 35382 | D24: 1
B25: Cabre | C25: 28273 | D25: 1
B26: Chen | C26: 28679 | D26: 1
B27: Corrêa | C27: 28375 | D27: 2
B28: Dalah | C28: 28348 | D28: 2
B29: Gomez-Perez | C29: 34950 | D29: 2
B30: Green | C30: 28614 | D30: 2
B31: Hamilton-James | C31: 28628 | D31: 2
B32: Hurt | C32: 28369 | D32: 1
B33: Iyengar | C33: 35920 | D33: 1
B34: Kracht | C34: 28294 | D34: 1
... B38: Woodward | C38: 29751 | D38: 1
A39: 2022 | B39: Ballesteros-Pomar | C39: 28270 | D39: 1
B40: Bea | C40: 34577 | D40: 1
B41: Buch | C41: 28925 | D41: 1
B42: Campa | C42: 28117 | D42: 1
B43: Coëffier | C43: 28116 | D43: 2
B44: Contreras-Bolívar | C44: 28042 | D44: 2
B45: CruzRivera | C45: 29074 | D45: 2
...

Sheet Structured
A1: Number | B1: YEAR | C1: First Author | D1: N
A2: 28292 | B2: 2021 | C2: Abbaspour | D2: 1
A3: 28140 | B3: 2024 | C3: Aguirre | D3: 1
A4: 32139 | B4: 2024 | C4: Ahmadi | D4: 1
A5: 35451 | B5: 2021 | C5: Alavi | D5: 1
A6: 28059 | B6: 2023 | C6: Anusitviwat | D6: 1
A7: 28270 | B7: 2022 | C7: Ballesteros-Pomar | D7: 1
A8: 28602 | B8: 2020 | C8: Bärebring | D8: 1
A9: 28371 | B9: 2021 | C9: BarretoSilva | D9: 1
A10: 33162 | B10: 2023 | C10: Baş | D10: 1
A11: 34577 | B11: 2022 | C11: Bea | D11: 1
A12: 28305 | B12: 2021 | C12: Bellafronte | D12: 1
A13: 35479 | B13: 2021 | C13: Bellafronte | D13: 1
... A103: 28214 | B103: 2020 | C103: Zambone | D103: 1

Sheet dir
A1: 28005 – Yanchis 2023.pdf | B1: =LEFT(A1,5) -> 28005
A2: 28042 – Contreras-Bolívar 2022.pdf | B2: =LEFT(A2,5) -> 28042
A3: 28046 – Kroll 2022.pdf | B3: =LEFT(A3,5) -> 28046
A4: 28056 – Tinsley 2022.pdf | B4: =LEFT(A4,5) -> 28056
A5: 28059 – Anusitviwat 2023.pdf | B5: =LEFT(A5,5) -> 28059
A6: 28087 – Carey 2023.pdf | B6: =LEFT(A6,5) -> 28087
A7: 28088 – Holmes 2022.pdf | B7: =LEFT(A7,5) -> 28088
A8: 28101 – Tinsley 2023.pdf | B8: =LEFT(A8,5) -> 28101
A9: 28112 – Herda 2022.pdf | B9: =LEFT(A9,5) -> 28112
A10: 28116 – Coëffier 2022.pdf | B10: =LEFT(A10,5) -> 28116
A11: 28117 – Campa 2022.pdf | B11: =LEFT(A11,5) -> 28117
A12: 28139 – Kiefer 2022.pdf | B12: =LEFT(A12,5) -> 28139
... A78: 35479 – Bellafronte 2021 | B78: =LEFT(A78,5) -> 35479
